"""
エラーシナリオフィクスチャの使用例

実際のテストでエラーシナリオフィクスチャを使用する方法を示すサンプル
"""

import pytest

from .loader import get_network_timeout_scenario, load_error_scenario


class TestErrorHandlingWithFixtures:
    """エラーシナリオフィクスチャを使用したエラーハンドリングテスト例"""

    def test_network_timeout_handling_with_fixture(self, network_timeout_scenario):
        """ネットワークタイムアウトのハンドリングテスト（フィクスチャ使用）"""
        # フィクスチャからシナリオデータを取得
        error_type = network_timeout_scenario["error_type"]
        error_message = network_timeout_scenario["error_message"]
        context = network_timeout_scenario["context"]
        expected_behavior = network_timeout_scenario["expected_behavior"]

        # エラーハンドリングロジックのテスト
        assert error_type == "TimeoutError"
        assert context["provider"] == "openai"
        assert "retry" in expected_behavior

        # 実際のエラーハンドリング実装をテスト（例）
        # with pytest.raises(TimeoutError, match=error_message):
        #     raise TimeoutError(error_message)

    def test_configuration_error_recovery(self, missing_api_key_scenario):
        """設定エラーからの復旧テスト（フィクスチャ使用）"""
        scenario = missing_api_key_scenario

        # 復旧戦略の確認
        recovery_strategy = scenario["recovery_strategy"]
        context = scenario["context"]

        assert "setup" in recovery_strategy.lower()
        assert context["provider"] == "openai"
        assert context["expected_key_name"] == "OPENAI_API_KEY"

        # 実際の復旧ロジックのテスト（例）
        # recovery_handler = ConfigurationErrorRecovery()
        # suggestions = recovery_handler.get_recovery_suggestions(scenario)
        # assert "api key" in suggestions[0].lower()

    def test_multiple_error_scenarios_handling(self):
        """複数のエラーシナリオの処理テスト（直接ローダー使用）"""
        scenarios = [
            load_error_scenario("network_errors", "timeout_error"),
            load_error_scenario("configuration_errors", "missing_api_key"),
            load_error_scenario("ai_processing_errors", "token_limit_exceeded"),
            load_error_scenario("file_system_errors", "log_file_not_found"),
        ]

        # すべてのシナリオが適切な構造を持つことを確認
        for scenario in scenarios:
            assert "error_type" in scenario
            assert "recovery_strategy" in scenario
            assert len(scenario["error_message"]) > 0

            # エラータイプに応じた処理のテスト（例）
            # error_handler = ErrorHandlerFactory.create(scenario["error_type"])
            # recovery_plan = error_handler.create_recovery_plan(scenario)
            # assert recovery_plan is not None

    def test_error_simulation_with_fixtures(self, simulate_network_error):
        """エラーシミュレーションフィクスチャの使用例"""
        # ネットワークエラーをシミュレート
        simulated_error = simulate_network_error("timeout_error")

        # シミュレートされたエラーが正しい型であることを確認
        assert isinstance(simulated_error, Exception)
        assert "timeout" in str(simulated_error).lower()

        # 実際のエラーハンドリングコードでテスト（例）
        # try:
        #     raise simulated_error
        # except Exception as e:
        #     error_handler = NetworkErrorHandler()
        #     result = error_handler.handle_error(e)
        #     assert result.should_retry is True

    @pytest.mark.parametrize(
        "scenario_name,expected_error_type",
        [
            ("timeout_error", "TimeoutError"),
            ("connection_error", "ConnectionError"),
            ("rate_limit_error", "RateLimitError"),
        ],
    )
    def test_parametrized_network_errors(self, scenario_name, expected_error_type):
        """パラメータ化されたネットワークエラーテスト"""
        scenario = load_error_scenario("network_errors", scenario_name)

        assert scenario["error_type"] == expected_error_type
        assert "network" in scenario["context"] or "provider" in scenario["context"]

        # 各エラータイプに応じた処理のテスト（例）
        # error_processor = NetworkErrorProcessor()
        # processing_result = error_processor.process(scenario)
        # assert processing_result.error_category == "network"


class TestErrorScenarioIntegration:
    """エラーシナリオの統合テスト例"""

    def test_ai_integration_error_handling(self):
        """AI統合でのエラーハンドリング統合テスト"""
        # 複数のAI関連エラーシナリオを使用
        token_limit_scenario = load_error_scenario("ai_processing_errors", "token_limit_exceeded")
        cost_limit_scenario = load_error_scenario("ai_processing_errors", "cost_limit_exceeded")

        # AI統合システムのエラーハンドリングをテスト（例）
        # with patch("src.ci_helper.ai.integration.AIIntegration") as mock_ai:
        #     mock_ai.analyze_log.side_effect = TokenLimitError(token_limit_scenario["error_message"])
        #
        #     ai_service = AIService()
        #     result = ai_service.analyze_with_fallback("large log content")
        #
        #     # フォールバック処理が実行されることを確認
        #     assert result.used_fallback is True
        #     assert "token limit" in result.warning_message.lower()

    def test_ci_execution_error_recovery(self):
        """CI実行エラーの復旧テスト"""
        docker_error_scenario = load_error_scenario("ci_execution_errors", "docker_not_running")
        act_error_scenario = load_error_scenario("ci_execution_errors", "act_not_installed")

        # CI実行システムのエラー復旧をテスト（例）
        # ci_runner = CIRunner()
        #
        # # Docker未起動エラーの処理
        # with patch("subprocess.run") as mock_run:
        #     mock_run.side_effect = Exception(docker_error_scenario["error_message"])
        #
        #     result = ci_runner.run_with_recovery("test.yml")
        #
        #     # 復旧提案が含まれることを確認
        #     assert "docker" in result.recovery_suggestions[0].lower()
        #     assert "start" in result.recovery_suggestions[0].lower()

    def test_security_error_prevention(self):
        """セキュリティエラーの予防テスト"""
        secret_detection_scenario = load_error_scenario("security_errors", "secret_detection_in_logs")

        # セキュリティチェックシステムのテスト（例）
        # security_scanner = SecurityScanner()
        #
        # # シークレット検出のテスト
        # log_content = "API key: sk-abc123def456..."
        # scan_result = security_scanner.scan_content(log_content)
        #
        # assert scan_result.has_secrets is True
        # assert len(scan_result.detected_secrets) > 0
        # assert scan_result.detected_secrets[0].type == "api_key"


class TestErrorScenarioCustomization:
    """エラーシナリオのカスタマイズ例"""

    def test_custom_error_scenario_creation(self):
        """カスタムエラーシナリオの作成例"""
        # 既存のシナリオをベースにカスタムシナリオを作成
        base_scenario = get_network_timeout_scenario()

        # カスタマイズされたシナリオ
        custom_scenario = {
            **base_scenario,
            "context": {
                **base_scenario["context"],
                "timeout_seconds": 60,  # より長いタイムアウト
                "retry_count": 3,
            },
            "expected_behavior": "retry_with_longer_timeout",
        }

        # カスタムシナリオでのテスト
        assert custom_scenario["context"]["timeout_seconds"] == 60
        assert custom_scenario["context"]["retry_count"] == 3
        assert "longer_timeout" in custom_scenario["expected_behavior"]

    def test_scenario_context_extension(self):
        """シナリオコンテキストの拡張例"""
        scenario = load_error_scenario("file_system_errors", "disk_space_full")

        # 追加のコンテキスト情報
        extended_context = {
            **scenario["context"],
            "cleanup_candidates": [".ci-helper/cache", "logs/"],
            "estimated_space_recovery": "50MB",
            "priority": "high",
        }

        # 拡張されたコンテキストでのテスト
        assert "cleanup_candidates" in extended_context
        assert extended_context["priority"] == "high"

        # 実際のクリーンアップロジックのテスト（例）
        # cleanup_manager = DiskSpaceCleanupManager()
        # cleanup_plan = cleanup_manager.create_plan(extended_context)
        # assert len(cleanup_plan.cleanup_targets) == 2
